Workbook
Name StartingBalance: Setup!$C$13

Sheet Expenses
C2: Expenses | D2: 42522 | E2: 42552 | F2: 42583 | G2: 42614 | H2: 42644 | I2: 42675 | J2: 42705 | K2: 42370 | L2: 42401 | M2: 42430 | N2: 42461 | O2: 42491 | P2: Total | Q2: Average | U2: Expenses | V2: 42522 | W2: 42552 | X2: 42583 | Y2: 42614 | Z2: 42644 | AA2: 42675 | AB2: 42705 | AC2: 42370 | AD2: 42401 | AE2: 42430 | AF2: 42461 | AG2: 42491 | AH2: Total | AI2: Average
A4: Debt | C4: Monthly totals: | D4: =sum(D5) -> 40 | E4: =sum(E5) -> 40 | F4: =sum(F5) -> 40 | G4: =sum(G5) -> 40 | H4: =sum(H5) -> 40 | I4: =sum(I5) -> 40 | J4: =sum(J5) -> 40 | K4: =sum(K5) -> 40 | ... O4: =sum(O5) -> 40 | P4: =sum(D4:O4) -> 480 | Q4: =iferror(average(D4:O4),"") -> 40 | S4: Debt | U4: Monthly totals: | V4: =sum(V5) -> 20 | W4: =sum(W5) -> 20 | X4: =sum(X5) -> 20 | Y4: =sum(Y5) -> 20 | Z4: =sum(Z5) -> 20 | AA4: =sum(AA5) -> 20 | AB4: =sum(AB5) -> 20 | AC4: =sum(AC5) -> 20 | ... AG4: =sum(AG5) -> 20 | AH4: =sum(V4:AG4) -> 240 | AI4: =iferror(average(V4:AG4),"") -> 20
C5: Household Card | D5: 40 | E5: 40 | F5: 40 | G5: 40 | H5: 40 | I5: 40 | J5: 40 | K5: 40 | L5: 40 | M5: 40 | N5: 40 | O5: 40 | P5: =sum(D5:O5) -> 480 | Q5: =iferror(average(D5:O5),0) -> 40 | U5: =CONCATENATE($C5," - Contrib") -> Household Card - Contrib | V5: =D5/Setup!$E$13 -> 20 | W5: =E5/Setup!$E$13 -> 20 | X5: =F5/Setup!$E$13 -> 20 | Y5: =G5/Setup!$E$13 -> 20 | Z5: =H5/Setup!$E$13 -> 20 | AA5: =I5/Setup!$E$13 -> 20 | AB5: =J5/Setup!$E$13 -> 20 | AC5: =K5/Setup!$E$13 -> 20 | ... AG5: =O5/Setup!$E$13 -> 20 | AH5: =sum(V5:AG5) -> 240 | AI5: =iferror(average(V5:AG5),0) -> 20
A9: Everyday | C9: Monthly totals: | D9: =sum(D10:D14) -> 335 | E9: =sum(E10:E14) -> 335 | F9: =sum(F10:F14) -> 335 | G9: =sum(G10:G14) -> 335 | H9: =sum(H10:H14) -> 335 | I9: =sum(I10:I14) -> 335 | J9: =sum(J10:J14) -> 335 | K9: =sum(K10:K14) -> 335 | ... O9: =sum(O10:O14) -> 335 | P9: =sum(D9:O9) -> 4020 | Q9: =iferror(average(D9:O9),"") -> 335 | S9: Everyday | U9: Monthly totals: | V9: =sum(V10:V14) -> 167.5 | W9: =sum(W10:W14) -> 167.5 | X9: =sum(X10:X14) -> 167.5 | Y9: =sum(Y10:Y14) -> 167.5 | Z9: =sum(Z10:Z14) -> 167.5 | AA9: =sum(AA10:AA14) -> 167.5 | AB9: =sum(AB10:AB14) -> 167.5 | AC9: =sum(AC10:AC14) -> 167.5 | ... AG9: =sum(AG10:AG14) -> 167.5 | AH9: =sum(V9:AG9) -> 2010 | AI9: =iferror(average(V9:AG9),"") -> 167.5
C10: Groceries | D10: 300 | E10: 300 | F10: 300 | G10: 300 | H10: 300 | I10: 300 | J10: 300 | K10: 300 | L10: 300 | M10: 300 | N10: 300 | O10: 300 | P10: =sum(D10:O10) -> 3600 | Q10: =iferror(average(D10:O10),0) -> 300 | U10: =CONCATENATE(C10," - Contibution") -> Groceries - Contibution | V10: =D10/Setup!$E$13 -> 150 | W10: =E10/Setup!$E$13 -> 150 | X10: =F10/Setup!$E$13 -> 150 | Y10: =G10/Setup!$E$13 -> 150 | Z10: =H10/Setup!$E$13 -> 150 | AA10: =I10/Setup!$E$13 -> 150 | AB10: =J10/Setup!$E$13 -> 150 | AC10: =K10/Setup!$E$13 -> 150 | ... AG10: =O10/Setup!$E$13 -> 150 | AH10: =sum(V10:AG10) -> 1800 | AI10: =iferror(average(V10:AG10),0) -> 150
C11: Laundry/dry cleaning | D11: 15 | E11: 15 | F11: 15 | G11: 15 | H11: 15 | I11: 15 | J11: 15 | K11: 15 | L11: 15 | M11: 15 | N11: 15 | O11: 15 | P11: =sum(D11:O11) -> 180 | Q11: =iferror(average(D11:O11),0) -> 15 | U11: =CONCATENATE(C11," - Contibution") -> Laundry/dry cleaning - Contibution | V11: =D11/Setup!$E$13 -> 7.5 | W11: =E11/Setup!$E$13 -> 7.5 | X11: =F11/Setup!$E$13 -> 7.5 | Y11: =G11/Setup!$E$13 -> 7.5 | Z11: =H11/Setup!$E$13 -> 7.5 | AA11: =I11/Setup!$E$13 -> 7.5 | AB11: =J11/Setup!$E$13 -> 7.5 | AC11: =K11/Setup!$E$13 -> 7.5 | ... AG11: =O11/Setup!$E$13 -> 7.5 | AH11: =sum(V11:AG11) -> 90 | AI11: =iferror(average(V11:AG11),0) -> 7.5
C12: Cleaning | D12: 10 | E12: 10 | F12: 10 | G12: 10 | H12: 10 | I12: 10 | J12: 10 | K12: 10 | L12: 10 | M12: 10 | N12: 10 | O12: 10 | P12: =sum(D12:O12) -> 120 | Q12: =iferror(average(D12:O12),0) -> 10 | U12: =CONCATENATE(C12," - Contibution") -> Cleaning - Contibution | V12: =D12/Setup!$E$13 -> 5 | W12: =E12/Setup!$E$13 -> 5 | X12: =F12/Setup!$E$13 -> 5 | Y12: =G12/Setup!$E$13 -> 5 | Z12: =H12/Setup!$E$13 -> 5 | AA12: =I12/Setup!$E$13 -> 5 | AB12: =J12/Setup!$E$13 -> 5 | AC12: =K12/Setup!$E$13 -> 5 | ... AG12: =O12/Setup!$E$13 -> 5 | AH12: =sum(V12:AG12) -> 60 | AI12: =iferror(average(V12:AG12),0) -> 5
C13: Subscriptions | D13: 10 | E13: 10 | F13: 10 | G13: 10 | H13: 10 | I13: 10 | J13: 10 | K13: 10 | L13: 10 | M13: 10 | N13: 10 | O13: 10 | P13: =sum(D13:O13) -> 120 | Q13: =iferror(average(D13:O13),0) -> 10 | U13: =CONCATENATE(C13," - Contibution") -> Subscriptions - Contibution | V13: =D13/Setup!$E$13 -> 5 | W13: =E13/Setup!$E$13 -> 5 | X13: =F13/Setup!$E$13 -> 5 | Y13: =G13/Setup!$E$13 -> 5 | Z13: =H13/Setup!$E$13 -> 5 | AA13: =I13/Setup!$E$13 -> 5 | AB13: =J13/Setup!$E$13 -> 5 | AC13: =K13/Setup!$E$13 -> 5 | ... AG13: =O13/Setup!$E$13 -> 5 | AH13: =sum(V13:AG13) -> 60 | AI13: =iferror(average(V13:AG13),0) -> 5
A17: Health/medical | C17: Monthly totals: | D17: =sum(D18:D21) -> 5 | E17: =sum(E18:E21) -> 5 | F17: =sum(F18:F21) -> 5 | G17: =sum(G18:G21) -> 5 | H17: =sum(H18:H21) -> 5 | I17: =sum(I18:I21) -> 5 | J17: =sum(J18:J21) -> 5 | K17: =sum(K18:K21) -> 5 | ... O17: =sum(O18:O21) -> 5 | P17: =sum(D17:O17) -> 60 | Q17: =iferror(average(D17:O17),"") -> 5 | S17: Health/medical | U17: Monthly totals: | V17: =sum(V18:V21) -> 2.5 | W17: =sum(W18:W21) -> 2.5 | X17: =sum(X18:X21) -> 2.5 | Y17: =sum(Y18:Y21) -> 2.5 | Z17: =sum(Z18:Z21) -> 2.5 | AA17: =sum(AA18:AA21) -> 2.5 | AB17: =sum(AB18:AB21) -> 2.5 | AC17: =sum(AC18:AC21) -> 2.5 | ... AG17: =sum(AG18:AG21) -> 2.5 | AH17: =sum(V17:AG17) -> 30 | AI17: =iferror(average(V17:AG17),"") -> 2.5
C18: Pharmacy | D18: 0 | E18: 0 | F18: 0 | G18: 0 | H18: 0 | I18: 0 | J18: 0 | K18: 0 | L18: 0 | M18: 0 | N18: 0 | O18: 0 | P18: =sum(D18:O18) -> 0 | Q18: =iferror(average(D18:O18),0) -> 0 | U18: =CONCATENATE(C18," - Contibution") -> Pharmacy - Contibution | V18: =D18/Setup!$E$13 -> 0 | W18: =E18/Setup!$E$13 -> 0 | X18: =F18/Setup!$E$13 -> 0 | Y18: =G18/Setup!$E$13 -> 0 | Z18: =H18/Setup!$E$13 -> 0 | AA18: =I18/Setup!$E$13 -> 0 | AB18: =J18/Setup!$E$13 -> 0 | AC18: =K18/Setup!$E$13 -> 0 | ... AG18: =O18/Setup!$E$13 -> 0 | AH18: =sum(V18:AG18) -> 0 | AI18: =iferror(average(V18:AG18),0) -> 0
C19: Vitamins & Minireals | D19: 5 | E19: 5 | F19: 5 | G19: 5 | H19: 5 | I19: 5 | J19: 5 | K19: 5 | L19: 5 | M19: 5 | N19: 5 | O19: 5 | P19: =sum(D19:O19) -> 60 | Q19: =iferror(average(D19:O19),0) -> 5 | U19: =CONCATENATE(C19," - Contibution") -> Vitamins & Minireals - Contibution | V19: =D19/Setup!$E$13 -> 2.5 | W19: =E19/Setup!$E$13 -> 2.5 | X19: =F19/Setup!$E$13 -> 2.5 | Y19: =G19/Setup!$E$13 -> 2.5 | Z19: =H19/Setup!$E$13 -> 2.5 | AA19: =I19/Setup!$E$13 -> 2.5 | AB19: =J19/Setup!$E$13 -> 2.5 | AC19: =K19/Setup!$E$13 -> 2.5 | ... AG19: =O19/Setup!$E$13 -> 2.5 | AH19: =sum(V19:AG19) -> 30 | AI19: =iferror(average(V19:AG19),0) -> 2.5
A22: Home | C22: Monthly totals: | D22: =sum(D23:D30) -> 554.94 | E22: =sum(E23:E30) -> 554.94 | F22: =sum(F23:F30) -> 554.94 | G22: =sum(G23:G30) -> 554.94 | H22: =sum(H23:H30) -> 554.94 | I22: =sum(I23:I30) -> 554.94 | J22: =sum(J23:J30) -> 554.94 | K22: =sum(K23:K30) -> 554.94 | ... O22: =sum(O23:O30) -> 554.94 | P22: =sum(D22:O22) -> 6659.28 | Q22: =iferror(average(D22:O22),"") -> 554.94 | S22: Home | U22: Monthly totals: | V22: =sum(V23:V30) -> 277.47 | W22: =sum(W23:W30) -> 277.47 | X22: =sum(X23:X30) -> 277.47 | Y22: =sum(Y23:Y30) -> 277.47 | Z22: =sum(Z23:Z30) -> 277.47 | AA22: =sum(AA23:AA30) -> 277.47 | AB22: =sum(AB23:AB30) -> 277.47 | AC22: =sum(AC23:AC30) -> 277.47 | ... AG22: =sum(AG23:AG30) -> 277.47 | AH22: =sum(V22:AG22) -> 3329.64 | AI22: =iferror(average(V22:AG22),"") -> 277.47
C23: Rent/mortgage | D23: 426.94 | E23: 426.94 | F23: 426.94 | G23: 426.94 | H23: 426.94 | I23: 426.94 | J23: 426.94 | K23: 426.94 | L23: 426.94 | M23: 426.94 | N23: 426.94 | O23: 426.94 | P23: =sum(D23:O23) -> 5123.28 | Q23: =iferror(average(D23:O23),0) -> 426.94 | U23: =CONCATENATE(C23," - Contibution") -> Rent/mortgage - Contibution | V23: =D23/Setup!$E$13 -> 213.47 | W23: =E23/Setup!$E$13 -> 213.47 | X23: =F23/Setup!$E$13 -> 213.47 | Y23: =G23/Setup!$E$13 -> 213.47 | Z23: =H23/Setup!$E$13 -> 213.47 | AA23: =I23/Setup!$E$13 -> 213.47 | AB23: =J23/Setup!$E$13 -> 213.47 | AC23: =K23/Setup!$E$13 -> 213.47 | ... AG23: =O23/Setup!$E$13 -> 213.47 | AH23: =sum(V23:AG23) -> 2561.64 | AI23: =iferror(average(V23:AG23),0) -> 213.47
C24: Council Tax | D24: 118 | E24: 118 | F24: 118 | G24: 118 | H24: 118 | I24: 118 | J24: 118 | K24: 118 | L24: 118 | M24: 118 | N24: 118 | O24: 118 | P24: =sum(D24:O24) -> 1416 | Q24: =iferror(average(D24:O24),0) -> 118 | U24: =CONCATENATE(C24," - Contibution") -> Council Tax - Contibution | V24: =D24/Setup!$E$13 -> 59 | W24: =E24/Setup!$E$13 -> 59 | X24: =F24/Setup!$E$13 -> 59 | Y24: =G24/Setup!$E$13 -> 59 | Z24: =H24/Setup!$E$13 -> 59 | AA24: =I24/Setup!$E$13 -> 59 | AB24: =J24/Setup!$E$13 -> 59 | AC24: =K24/Setup!$E$13 -> 59 | ... AG24: =O24/Setup!$E$13 -> 59 | AH24: =sum(V24:AG24) -> 708 | AI24: =iferror(average(V24:AG24),0) -> 59
C25: Furnishings | D25: 0 | E25: 0 | F25: 0 | G25: 0 | H25: 0 | I25: 0 | J25: 0 | K25: 0 | L25: 0 | M25: 0 | N25: 0 | O25: 0 | P25: =sum(D25:O25) -> 0 | Q25: =iferror(average(D25:O25),0) -> 0 | U25: =CONCATENATE(C25," - Contibution") -> Furnishings - Contibution | V25: =D25/Setup!$E$13 -> 0 | W25: =E25/Setup!$E$13 -> 0 | X25: =F25/Setup!$E$13 -> 0 | Y25: =G25/Setup!$E$13 -> 0 | Z25: =H25/Setup!$E$13 -> 0 | AA25: =I25/Setup!$E$13 -> 0 | AB25: =J25/Setup!$E$13 -> 0 | AC25: =K25/Setup!$E$13 -> 0 | ... AG25: =O25/Setup!$E$13 -> 0 | AH25: =sum(V25:AG25) -> 0 | AI25: =iferror(average(V25:AG25),0) -> 0
C26: Supplies | D26: 0 | E26: 0 | F26: 0 | G26: 0 | H26: 0 | I26: 0 | J26: 0 | K26: 0 | L26: 0 | M26: 0 | N26: 0 | O26: 0 | P26: =sum(D26:O26) -> 0 | Q26: =iferror(average(D26:O26),0) -> 0 | U26: =CONCATENATE(C26," - Contibution") -> Supplies - Contibution | V26: =D26/Setup!$E$13 -> 0 | W26: =E26/Setup!$E$13 -> 0 | X26: =F26/Setup!$E$13 -> 0 | Y26: =G26/Setup!$E$13 -> 0 | Z26: =H26/Setup!$E$13 -> 0 | AA26: =I26/Setup!$E$13 -> 0 | AB26: =J26/Setup!$E$13 -> 0 | AC26: =K26/Setup!$E$13 -> 0 | ... AG26: =O26/Setup!$E$13 -> 0 | AH26: =sum(V26:AG26) -> 0 | AI26: =iferror(average(V26:AG26),0) -> 0
C27: Maintenance | D27: 10 | E27: 10 | F27: 10 | G27: 10 | H27: 10 | I27: 10 | J27: 10 | K27: 10 | L27: 10 | M27: 10 | N27: 10 | O27: 10 | P27: =sum(D27:O27) -> 120 | Q27: =iferror(average(D27:O27),0) -> 10 | U27: =CONCATENATE(C27," - Contibution") -> Maintenance - Contibution | V27: =D27/Setup!$E$13 -> 5 | W27: =E27/Setup!$E$13 -> 5 | X27: =F27/Setup!$E$13 -> 5 | Y27: =G27/Setup!$E$13 -> 5 | Z27: =H27/Setup!$E$13 -> 5 | AA27: =I27/Setup!$E$13 -> 5 | AB27: =J27/Setup!$E$13 -> 5 | AC27: =K27/Setup!$E$13 -> 5 | ... AG27: =O27/Setup!$E$13 -> 5 | AH27: =sum(V27:AG27) -> 60 | AI27: =iferror(average(V27:AG27),0) -> 5
C28: Improvements | D28: 0 | E28: 0 | F28: 0 | G28: 0 | H28: 0 | I28: 0 | J28: 0 | K28: 0 | L28: 0 | M28: 0 | N28: 0 | O28: 0 | P28: =sum(D28:O28) -> 0 | Q28: =iferror(average(D28:O28),0) -> 0 | U28: =CONCATENATE(C28," - Contibution") -> Improvements - Contibution | V28: =D28/Setup!$E$13 -> 0 | W28: =E28/Setup!$E$13 -> 0 | X28: =F28/Setup!$E$13 -> 0 | Y28: =G28/Setup!$E$13 -> 0 | Z28: =H28/Setup!$E$13 -> 0 | AA28: =I28/Setup!$E$13 -> 0 | AB28: =J28/Setup!$E$13 -> 0 | AC28: =K28/Setup!$E$13 -> 0 | ... AG28: =O28/Setup!$E$13 -> 0 | AH28: =sum(V28:AG28) -> 0 | AI28: =iferror(average(V28:AG28),0) -> 0
A31: Insurance | C31: Monthly totals: | D31: =sum(D32:D35) -> 99.65 | E31: =sum(E32:E35) -> 99.65 | F31: =sum(F32:F35) -> 99.65 | G31: =sum(G32:G35) -> 99.65 | H31: =sum(H32:H35) -> 99.65 | I31: =sum(I32:I35) -> 99.65 | J31: =sum(J32:J35) -> 99.65 | K31: =sum(K32:K35) -> 99.65 | ... O31: =sum(O32:O35) -> 99.65 | P31: =sum(D31:O31) -> 1195.8 | Q31: =iferror(average(D31:O31),"") -> 99.65 | S31: Insurance | U31: Monthly totals: | V31: =sum(V32:V35) -> 49.825 | W31: =sum(W32:W35) -> 49.825 | X31: =sum(X32:X35) -> 49.825 | Y31: =sum(Y32:Y35) -> 49.825 | Z31: =sum(Z32:Z35) -> 49.825 | AA31: =sum(AA32:AA35) -> 49.825 | AB31: =sum(AB32:AB35) -> 49.825 | AC31: =sum(AC32:AC35) -> 49.825 | ... AG31: =sum(AG32:AG35) -> 49.825 | AH31: =sum(V31:AG31) -> 597.9 | AI31: =iferror(average(V31:AG31),"") -> 49.825
C32: Home | D32: 31.91 | E32: 31.91 | F32: 31.91 | G32: 31.91 | H32: 31.91 | I32: 31.91 | J32: 31.91 | K32: 31.91 | L32: 31.91 | M32: 31.91 | N32: 31.91 | O32: 31.91 | P32: =sum(D32:O32) -> 382.92 | Q32: =iferror(average(D32:O32),0) -> 31.91 | U32: =CONCATENATE(C32," - Contibution") -> Home - Contibution | V32: =D32/Setup!$E$13 -> 15.955 | W32: =E32/Setup!$E$13 -> 15.955 | X32: =F32/Setup!$E$13 -> 15.955 | Y32: =G32/Setup!$E$13 -> 15.955 | Z32: =H32/Setup!$E$13 -> 15.955 | AA32: =I32/Setup!$E$13 -> 15.955 | AB32: =J32/Setup!$E$13 -> 15.955 | AC32: =K32/Setup!$E$13 -> 15.955 | ... AG32: =O32/Setup!$E$13 -> 15.955 | AH32: =sum(V32:AG32) -> 191.46 | AI32: =iferror(average(V32:AG32),0) -> 15.955
C33: Pet | D33: 67.74 | E33: 67.74 | F33: 67.74 | G33: 67.74 | H33: 67.74 | I33: 67.74 | J33: 67.74 | K33: 67.74 | L33: 67.74 | M33: 67.74 | N33: 67.74 | O33: 67.74 | P33: =sum(D33:O33) -> 812.88 | Q33: =iferror(average(D33:O33),0) -> 67.74 | U33: =CONCATENATE(C33," - Contibution") -> Pet - Contibution | V33: =D33/Setup!$E$13 -> 33.87 | W33: =E33/Setup!$E$13 -> 33.87 | X33: =F33/Setup!$E$13 -> 33.87 | Y33: =G33/Setup!$E$13 -> 33.87 | Z33: =H33/Setup!$E$13 -> 33.87 | AA33: =I33/Setup!$E$13 -> 33.87 | AB33: =J33/Setup!$E$13 -> 33.87 | AC33: =K33/Setup!$E$13 -> 33.87 | ... AG33: =O33/Setup!$E$13 -> 33.87 | AH33: =sum(V33:AG33) -> 406.44 | AI33: =iferror(average(V33:AG33),0) -> 33.87
A36: Pets | C36: Monthly totals: | D36: =sum(D37:D42) -> 90 | E36: =sum(E37:E42) -> 90 | F36: =sum(F37:F42) -> 90 | G36: =sum(G37:G42) -> 90 | H36: =sum(H37:H42) -> 90 | I36: =sum(I37:I42) -> 90 | J36: =sum(J37:J42) -> 90 | K36: =sum(K37:K42) -> 90 | ... O36: =sum(O37:O42) -> 90 | P36: =sum(D36:O36) -> 1080 | Q36: =iferror(average(D36:O36),"") -> 90 | S36: Pets | U36: Monthly totals: | V36: =sum(V37:V42) -> 45 | W36: =sum(W37:W42) -> 45 | X36: =sum(X37:X42) -> 45 | Y36: =sum(Y37:Y42) -> 45 | Z36: =sum(Z37:Z42) -> 45 | AA36: =sum(AA37:AA42) -> 45 | AB36: =sum(AB37:AB42) -> 45 | AC36: =sum(AC37:AC42) -> 45 | ... AG36: =sum(AG37:AG42) -> 45 | AH36: =sum(V36:AG36) -> 540 | AI36: =iferror(average(V36:AG36),"") -> 45
C37: Food | D37: 65 | E37: 65 | F37: 65 | G37: 65 | H37: 65 | I37: 65 | J37: 65 | K37: 65 | L37: 65 | M37: 65 | N37: 65 | O37: 65 | P37: =sum(D37:O37) -> 780 | Q37: =iferror(average(D37:O37),0) -> 65 | U37: =CONCATENATE(C37," - Contibution") -> Food - Contibution | V37: =D37/Setup!$E$13 -> 32.5 | W37: =E37/Setup!$E$13 -> 32.5 | X37: =F37/Setup!$E$13 -> 32.5 | Y37: =G37/Setup!$E$13 -> 32.5 | Z37: =H37/Setup!$E$13 -> 32.5 | AA37: =I37/Setup!$E$13 -> 32.5 | AB37: =J37/Setup!$E$13 -> 32.5 | AC37: =K37/Setup!$E$13 -> 32.5 | ... AG37: =O37/Setup!$E$13 -> 32.5 | AH37: =sum(V37:AG37) -> 390 | AI37: =iferror(average(V37:AG37),0) -> 32.5
C38: Vet/medical | D38: 25 | E38: 25 | F38: 25 | G38: 25 | H38: 25 | I38: 25 | J38: 25 | K38: 25 | L38: 25 | M38: 25 | N38: 25 | O38: 25 | P38: =sum(D38:O38) -> 300 | Q38: =iferror(average(D38:O38),0) -> 25 | U38: =CONCATENATE(C38," - Contibution") -> Vet/medical - Contibution | V38: =D38/Setup!$E$13 -> 12.5 | W38: =E38/Setup!$E$13 -> 12.5 | X38: =F38/Setup!$E$13 -> 12.5 | Y38: =G38/Setup!$E$13 -> 12.5 | Z38: =H38/Setup!$E$13 -> 12.5 | AA38: =I38/Setup!$E$13 -> 12.5 | AB38: =J38/Setup!$E$13 -> 12.5 | AC38: =K38/Setup!$E$13 -> 12.5 | ... AG38: =O38/Setup!$E$13 -> 12.5 | AH38: =sum(V38:AG38) -> 150 | AI38: =iferror(average(V38:AG38),0) -> 12.5
C39: Toys | D39: 0 | E39: 0 | F39: 0 | G39: 0 | H39: 0 | I39: 0 | J39: 0 | K39: 0 | L39: 0 | M39: 0 | N39: 0 | O39: 0 | P39: =sum(D39:O39) -> 0 | Q39: =iferror(average(D39:O39),0) -> 0 | U39: =CONCATENATE(C39," - Contibution") -> Toys - Contibution | V39: =D39/Setup!$E$13 -> 0 | W39: =E39/Setup!$E$13 -> 0 | X39: =F39/Setup!$E$13 -> 0 | Y39: =G39/Setup!$E$13 -> 0 | Z39: =H39/Setup!$E$13 -> 0 | AA39: =I39/Setup!$E$13 -> 0 | AB39: =J39/Setup!$E$13 -> 0 | AC39: =K39/Setup!$E$13 -> 0 | ... AG39: =O39/Setup!$E$13 -> 0 | AH39: =sum(V39:AG39) -> 0 | AI39: =iferror(average(V39:AG39),0) -> 0
C40: Supplies | D40: 0 | E40: 0 | F40: 0 | G40: 0 | H40: 0 | I40: 0 | J40: 0 | K40: 0 | L40: 0 | M40: 0 | N40: 0 | O40: 0 | P40: =sum(D40:O40) -> 0 | Q40: =iferror(average(D40:O40),0) -> 0 | U40: =CONCATENATE(C40," - Contibution") -> Supplies - Contibution | V40: =D40/Setup!$E$13 -> 0 | W40: =E40/Setup!$E$13 -> 0 | X40: =F40/Setup!$E$13 -> 0 | Y40: =G40/Setup!$E$13 -> 0 | Z40: =H40/Setup!$E$13 -> 0 | AA40: =I40/Setup!$E$13 -> 0 | AB40: =J40/Setup!$E$13 -> 0 | AC40: =K40/Setup!$E$13 -> 0 | ... AG40: =O40/Setup!$E$13 -> 0 | AH40: =sum(V40:AG40) -> 0 | AI40: =iferror(average(V40:AG40),0) -> 0
A43: Technology | C43: Monthly totals: | D43: =sum(D44:D48) -> 10 | E43: =sum(E44:E48) -> 10 | F43: =sum(F44:F48) -> 10 | G43: =sum(G44:G48) -> 10 | H43: =sum(H44:H48) -> 10 | I43: =sum(I44:I48) -> 10 | J43: =sum(J44:J48) -> 10 | K43: =sum(K44:K48) -> 10 | ... O43: =sum(O44:O48) -> 10 | P43: =sum(D43:O43) -> 120 | Q43: =iferror(average(D43:O43),"") -> 10 | S43: Technology | U43: Monthly totals: | V43: =sum(V44:V48) -> 5 | W43: =sum(W44:W48) -> 5 | X43: =sum(X44:X48) -> 5 | Y43: =sum(Y44:Y48) -> 5 | Z43: =sum(Z44:Z48) -> 5 | AA43: =sum(AA44:AA48) -> 5 | AB43: =sum(AB44:AB48) -> 5 | AC43: =sum(AC44:AC48) -> 5 | ... AG43: =sum(AG44:AG48) -> 5 | AH43: =sum(V43:AG43) -> 60 | AI43: =iferror(average(V43:AG43),"") -> 5
C44: Online services | D44: 10 | E44: 10 | F44: 10 | G44: 10 | H44: 10 | I44: 10 | J44: 10 | K44: 10 | L44: 10 | M44: 10 | N44: 10 | O44: 10 | P44: =sum(D44:O44) -> 120 | Q44: =iferror(average(D44:O44),0) -> 10 | U44: =CONCATENATE(C44," - Contibution") -> Online services - Contibution | V44: =D44/Setup!$E$13 -> 5 | W44: =E44/Setup!$E$13 -> 5 | X44: =F44/Setup!$E$13 -> 5 | Y44: =G44/Setup!$E$13 -> 5 | Z44: =H44/Setup!$E$13 -> 5 | AA44: =I44/Setup!$E$13 -> 5 | AB44: =J44/Setup!$E$13 -> 5 | AC44: =K44/Setup!$E$13 -> 5 | ... AG44: =O44/Setup!$E$13 -> 5 | AH44: =sum(V44:AG44) -> 60 | AI44: =iferror(average(V44:AG44),0) -> 5
C45: Hardware | D45: 0 | E45: 0 | F45: 0 | G45: 0 | H45: 0 | I45: 0 | J45: 0 | K45: 0 | L45: 0 | M45: 0 | N45: 0 | O45: 0 | P45: =sum(D45:O45) -> 0 | Q45: =iferror(average(D45:O45),0) -> 0 | U45: =CONCATENATE(C45," - Contibution") -> Hardware - Contibution | V45: =D45/Setup!$E$13 -> 0 | W45: =E45/Setup!$E$13 -> 0 | X45: =F45/Setup!$E$13 -> 0 | Y45: =G45/Setup!$E$13 -> 0 | Z45: =H45/Setup!$E$13 -> 0 | AA45: =I45/Setup!$E$13 -> 0 | AB45: =J45/Setup!$E$13 -> 0 | AC45: =K45/Setup!$E$13 -> 0 | ... AG45: =O45/Setup!$E$13 -> 0 | AH45: =sum(V45:AG45) -> 0 | AI45: =iferror(average(V45:AG45),0) -> 0
C46: Software | D46: 0 | E46: 0 | F46: 0 | G46: 0 | H46: 0 | I46: 0 | J46: 0 | K46: 0 | L46: 0 | M46: 0 | N46: 0 | O46: 0 | P46: =sum(D46:O46) -> 0 | Q46: =iferror(average(D46:O46),0) -> 0 | U46: =CONCATENATE(C46," - Contibution") -> Software - Contibution | V46: =D46/Setup!$E$13 -> 0 | W46: =E46/Setup!$E$13 -> 0 | X46: =F46/Setup!$E$13 -> 0 | Y46: =G46/Setup!$E$13 -> 0 | Z46: =H46/Setup!$E$13 -> 0 | AA46: =I46/Setup!$E$13 -> 0 | AB46: =J46/Setup!$E$13 -> 0 | AC46: =K46/Setup!$E$13 -> 0 | ... AG46: =O46/Setup!$E$13 -> 0 | AH46: =sum(V46:AG46) -> 0 | AI46: =iferror(average(V46:AG46),0) -> 0
A49: Transportation | C49: Monthly totals: | D49: =sum(D50:D53) -> 95 | E49: =sum(E50:E53) -> 90 | F49: =sum(F50:F53) -> 90 | G49: =sum(G50:G53) -> 90 | H49: =sum(H50:H53) -> 95 | I49: =sum(I50:I53) -> 90 | J49: =sum(J50:J53) -> 90 | K49: =sum(K50:K53) -> 90 | ... O49: =sum(O50:O53) -> 90 | P49: =sum(D49:O49) -> 1095 | Q49: =iferror(average(D49:O49),"") -> 91.25 | S49: Transportation | U49: Monthly totals: | V49: =sum(V50:V53) -> 47.5 | W49: =sum(W50:W53) -> 45 | X49: =sum(X50:X53) -> 45 | Y49: =sum(Y50:Y53) -> 45 | Z49: =sum(Z50:Z53) -> 47.5 | AA49: =sum(AA50:AA53) -> 45 | AB49: =sum(AB50:AB53) -> 45 | AC49: =sum(AC50:AC53) -> 45 | ... AG49: =sum(AG50:AG53) -> 45 | AH49: =sum(V49:AG49) -> 547.5 | AI49: =iferror(average(V49:AG49),"") -> 45.625
C50: Fuel | D50: 90 | E50: 90 | F50: 90 | G50: 90 | H50: 90 | I50: 90 | J50: 90 | K50: 90 | L50: 90 | M50: 90 | N50: 90 | O50: 90 | P50: =sum(D50:O50) -> 1080 | Q50: =iferror(average(D50:O50),0) -> 90 | U50: =CONCATENATE(C50," - Contibution") -> Fuel - Contibution | V50: =D50/Setup!$E$13 -> 45 | W50: =E50/Setup!$E$13 -> 45 | X50: =F50/Setup!$E$13 -> 45 | Y50: =G50/Setup!$E$13 -> 45 | Z50: =H50/Setup!$E$13 -> 45 | AA50: =I50/Setup!$E$13 -> 45 | AB50: =J50/Setup!$E$13 -> 45 | AC50: =K50/Setup!$E$13 -> 45 | ... AG50: =O50/Setup!$E$13 -> 45 | AH50: =sum(V50:AG50) -> 540 | AI50: =iferror(average(V50:AG50),0) -> 45
C51: Repairs | D51: 0 | E51: 0 | F51: 0 | G51: 0 | H51: 0 | I51: 0 | J51: 0 | K51: 0 | L51: 0 | M51: 0 | N51: 0 | O51: 0 | P51: =sum(D51:O51) -> 0 | Q51: =iferror(average(D51:O51),0) -> 0 | U51: =CONCATENATE(C51," - Contibution") -> Repairs - Contibution | V51: =D51/Setup!$E$13 -> 0 | W51: =E51/Setup!$E$13 -> 0 | X51: =F51/Setup!$E$13 -> 0 | Y51: =G51/Setup!$E$13 -> 0 | Z51: =H51/Setup!$E$13 -> 0 | AA51: =I51/Setup!$E$13 -> 0 | AB51: =J51/Setup!$E$13 -> 0 | AC51: =K51/Setup!$E$13 -> 0 | ... AG51: =O51/Setup!$E$13 -> 0 | AH51: =sum(V51:AG51) -> 0 | AI51: =iferror(average(V51:AG51),0) -> 0
C52: Registration/license | D52: 0 | E52: 0 | F52: 0 | G52: 0 | H52: 0 | I52: 0 | J52: 0 | K52: 0 | L52: 0 | M52: 0 | N52: 0 | O52: 0 | P52: =sum(D52:O52) -> 0 | Q52: =iferror(average(D52:O52),0) -> 0 | U52: =CONCATENATE(C52," - Contibution") -> Registration/license - Contibution | V52: =D52/Setup!$E$13 -> 0 | W52: =E52/Setup!$E$13 -> 0 | X52: =F52/Setup!$E$13 -> 0 | Y52: =G52/Setup!$E$13 -> 0 | Z52: =H52/Setup!$E$13 -> 0 | AA52: =I52/Setup!$E$13 -> 0 | AB52: =J52/Setup!$E$13 -> 0 | AC52: =K52/Setup!$E$13 -> 0 | ... AG52: =O52/Setup!$E$13 -> 0 | AH52: =sum(V52:AG52) -> 0 | AI52: =iferror(average(V52:AG52),0) -> 0
C53: Supplies | D53: 5 | E53: 0 | F53: 0 | G53: 0 | H53: 5 | I53: 0 | J53: 0 | K53: 0 | L53: 5 | M53: 0 | N53: 0 | O53: 0 | P53: =sum(D53:O53) -> 15 | Q53: =iferror(average(D53:O53),0) -> 1.25 | U53: =CONCATENATE(C53," - Contibution") -> Supplies - Contibution | V53: =D53/Setup!$E$13 -> 2.5 | W53: =E53/Setup!$E$13 -> 0 | X53: =F53/Setup!$E$13 -> 0 | Y53: =G53/Setup!$E$13 -> 0 | Z53: =H53/Setup!$E$13 -> 2.5 | AA53: =I53/Setup!$E$13 -> 0 | AB53: =J53/Setup!$E$13 -> 0 | AC53: =K53/Setup!$E$13 -> 0 | ... AG53: =O53/Setup!$E$13 -> 0 | AH53: =sum(V53:AG53) -> 7.5 | AI53: =iferror(average(V53:AG53),0) -> 0.625
A56: Utilities | C56: Monthly totals: | D56: =sum(D57:D65) -> 158.37 | E56: =sum(E57:E65) -> 158.37 | F56: =sum(F57:F65) -> 223.37 | G56: =sum(G57:G65) -> 158.37 | H56: =sum(H57:H65) -> 223.37 | I56: =sum(I57:I65) -> 223.37 | J56: =sum(J57:J65) -> 223.37 | K56: =sum(K57:K65) -> 223.37 | ... O56: =sum(O57:O65) -> 158.37 | P56: =sum(D56:O56) -> 2355.44 | Q56: =iferror(average(D56:O56),"") -> 196.28667 | S56: Utilities | U56: Monthly totals: | V56: =sum(V57:V65) -> 79.185 | W56: =sum(W57:W65) -> 79.185 | X56: =sum(X57:X65) -> 111.685 | Y56: =sum(Y57:Y65) -> 79.185 | Z56: =sum(Z57:Z65) -> 111.685 | AA56: =sum(AA57:AA65) -> 111.685 | AB56: =sum(AB57:AB65) -> 111.685 | AC56: =sum(AC57:AC65) -> 111.685 | ... AG56: =sum(AG57:AG65) -> 79.185 | AH56: =sum(V56:AG56) -> 1177.72 | AI56: =iferror(average(V56:AG56),"") -> 98.143333
C57: Phone | D57: 7 | E57: 7 | F57: 7 | G57: 7 | H57: 7 | I57: 7 | J57: 7 | K57: 7 | L57: 7 | M57: 7 | N57: 7 | O57: 7 | P57: =sum(D57:O57) -> 84 | Q57: =iferror(average(D57:O57),0) -> 7 | U57: =CONCATENATE(C57," - Contibution") -> Phone - Contibution | V57: =D57/Setup!$E$13 -> 3.5 | W57: =E57/Setup!$E$13 -> 3.5 | X57: =F57/Setup!$E$13 -> 3.5 | Y57: =G57/Setup!$E$13 -> 3.5 | Z57: =H57/Setup!$E$13 -> 3.5 | AA57: =I57/Setup!$E$13 -> 3.5 | AB57: =J57/Setup!$E$13 -> 3.5 | AC57: =K57/Setup!$E$13 -> 3.5 | ... AG57: =O57/Setup!$E$13 -> 3.5 | AH57: =sum(V57:AG57) -> 42 | AI57: =iferror(average(V57:AG57),0) -> 3.5
C58: TV | D58: 13.37 | E58: 13.37 | F58: 13.37 | G58: 13.37 | H58: 13.37 | I58: 13.37 | J58: 13.37 | K58: 13.37 | L58: 13.37 | M58: 13.37 | N58: 13.37 | O58: 13.37 | P58: =sum(D58:O58) -> 160.44 | Q58: =iferror(average(D58:O58),0) -> 13.37 | U58: =CONCATENATE(C58," - Contibution") -> TV - Contibution | V58: =D58/Setup!$E$13 -> 6.685 | W58: =E58/Setup!$E$13 -> 6.685 | X58: =F58/Setup!$E$13 -> 6.685 | Y58: =G58/Setup!$E$13 -> 6.685 | Z58: =H58/Setup!$E$13 -> 6.685 | AA58: =I58/Setup!$E$13 -> 6.685 | AB58: =J58/Setup!$E$13 -> 6.685 | AC58: =K58/Setup!$E$13 -> 6.685 | ... AG58: =O58/Setup!$E$13 -> 6.685 | AH58: =sum(V58:AG58) -> 80.22 | AI58: =iferror(average(V58:AG58),0) -> 6.685
C59: Internet | D59: 28 | E59: 28 | F59: 28 | G59: 28 | H59: 28 | I59: 28 | J59: 28 | K59: 28 | L59: 28 | M59: 28 | N59: 28 | O59: 28 | P59: =sum(D59:O59) -> 336 | Q59: =iferror(average(D59:O59),0) -> 28 | U59: =CONCATENATE(C59," - Contibution") -> Internet - Contibution | V59: =D59/Setup!$E$13 -> 14 | W59: =E59/Setup!$E$13 -> 14 | X59: =F59/Setup!$E$13 -> 14 | Y59: =G59/Setup!$E$13 -> 14 | Z59: =H59/Setup!$E$13 -> 14 | AA59: =I59/Setup!$E$13 -> 14 | AB59: =J59/Setup!$E$13 -> 14 | AC59: =K59/Setup!$E$13 -> 14 | ... AG59: =O59/Setup!$E$13 -> 14 | AH59: =sum(V59:AG59) -> 168 | AI59: =iferror(average(V59:AG59),0) -> 14
C60: Electricity | D60: 50 | E60: 50 | F60: 50 | G60: 50 | H60: 50 | I60: 50 | J60: 50 | K60: 50 | L60: 50 | M60: 50 | N60: 50 | O60: 50 | P60: =sum(D60:O60) -> 600 | Q60: =iferror(average(D60:O60),0) -> 50 | U60: =CONCATENATE(C60," - Contibution") -> Electricity - Contibution | V60: =D60/Setup!$E$13 -> 25 | W60: =E60/Setup!$E$13 -> 25 | X60: =F60/Setup!$E$13 -> 25 | Y60: =G60/Setup!$E$13 -> 25 | Z60: =H60/Setup!$E$13 -> 25 | AA60: =I60/Setup!$E$13 -> 25 | AB60: =J60/Setup!$E$13 -> 25 | AC60: =K60/Setup!$E$13 -> 25 | ... AG60: =O60/Setup!$E$13 -> 25 | AH60: =sum(V60:AG60) -> 300 | AI60: =iferror(average(V60:AG60),0) -> 25
...

Sheet Income
C2: Income | D2: 42522 | E2: 42552 | F2: 42583 | G2: 42614 | H2: 42644 | I2: 42675 | J2: 42705 | K2: 42370 | L2: 42401 | M2: 42430 | N2: 42461 | O2: 42491 | P2: Total | Q2: Average
A3: Contributions | C3: Monthly totals: | D3: =sum(D4:D9) -> 1547.96 | E3: =sum(E4:E9) -> 1659.552 | F3: =sum(F4:F9) -> 1737.552 | G3: =sum(G4:G9) -> 1659.552 | H3: =sum(H4:H9) -> 1743.552 | I3: =sum(I4:I9) -> 1737.552 | J3: =sum(J4:J9) -> 1737.552 | K3: =sum(K4:K9) -> 1737.552 | ... O3: =sum(O4:O9) -> 1659.552 | P3: =sum(D3:O3) -> 20361.032 | Q3: =iferror(average(D3:O3),"") -> 1696.7527
C4: Money from James | D4: =Expenses!V$69 -> 693.98 | E4: =Expenses!W$69 -> 691.48 | F4: =Expenses!X$69 -> 723.98 | G4: =Expenses!Y$69 -> 691.48 | H4: =Expenses!Z$69 -> 726.48 | I4: =Expenses!AA$69 -> 723.98 | J4: =Expenses!AB$69 -> 723.98 | K4: =Expenses!AC$69 -> 723.98 | ... O4: =Expenses!AG$69 -> 691.48 | P4: =sum(D4:O4) -> 8532.76 | Q4: =iferror(average(D4:O4),0) -> 711.06333
C5: Money from Merrill | D5: =Expenses!V$69 -> 693.98 | E5: =Expenses!W$69 -> 691.48 | F5: =Expenses!X$69 -> 723.98 | G5: =Expenses!Y$69 -> 691.48 | H5: =Expenses!Z$69 -> 726.48 | I5: =Expenses!AA$69 -> 723.98 | J5: =Expenses!AB$69 -> 723.98 | K5: =Expenses!AC$69 -> 723.98 | ... O5: =Expenses!AG$69 -> 691.48 | P5: =sum(D5:O5) -> 8532.76 | Q5: =iferror(average(D5:O5),0) -> 711.06333
C6: Money from a Lodger | D6: 0 | E6: 0 | F6: 0 | G6: 0 | H6: 0 | I6: 0 | J6: 0 | K6: 0 | L6: 0 | M6: 0 | N6: 0 | O6: 0 | P6: =sum(D6:O6) -> 0 | Q6: =iferror(average(D6:O6),0) -> 0
C7: Other | D7: 160 | E7: =E5*2/5 -> 276.592 | F7: =F5*2/5 -> 289.592 | G7: =G5*2/5 -> 276.592 | H7: =H5*2/5 -> 290.592 | I7: =I5*2/5 -> 289.592 | J7: =J5*2/5 -> 289.592 | K7: =K5*2/5 -> 289.592 | L7: =L5*2/5 -> 290.592 | ... O7: =O5*2/5 -> 276.592 | P7: =sum(D7:O7) -> 3295.512 | Q7: =iferror(average(D7:O7),0) -> 274.626
A10: Other | C10: Monthly totals: | D10: =sum(D11:D14) -> 0 | E10: =sum(E11:E14) -> 0 | F10: =sum(F11:F14) -> 0 | G10: =sum(G11:G14) -> 0 | H10: =sum(H11:H14) -> 0 | I10: =sum(I11:I14) -> 0 | J10: =sum(J11:J14) -> 0 | K10: =sum(K11:K14) -> 0 | ... O10: =sum(O11:O14) -> 0 | P10: =sum(D10:O10) -> 0 | Q10: =iferror(average(D10:O10),"") -> 0
C11: Refunds | D11: 0 | E11: 0 | F11: 0 | G11: 0 | H11: 0 | I11: 0 | J11: 0 | K11: 0 | L11: 0 | M11: 0 | N11: 0 | O11: 0 | P11: =sum(D11:O11) -> 0 | Q11: =iferror(average(D11:O11),0) -> 0
C12: Other | D12: 0 | E12: 0 | F12: 0 | G12: 0 | H12: 0 | I12: 0 | J12: 0 | K12: 0 | L12: 0 | M12: 0 | N12: 0 | O12: 0 | P12: =sum(D12:O12) -> 0 | Q12: =iferror(average(D12:O12),0) -> 0

Sheet Summary
C17: Summary
D18: =Expenses!D$2 -> 42522 | E18: =Expenses!E$2 -> 42552 | F18: =Expenses!F$2 -> 42583 | G18: =Expenses!G$2 -> 42614 | H18: =Expenses!H$2 -> 42644 | I18: =Expenses!I$2 -> 42675 | J18: =Expenses!J$2 -> 42705 | K18: =Expenses!K$2 -> 42370 | ... O18: =Expenses!O$2 -> 42491 | P18: Total | Q18: Average
C19: Income | D19: =sum(D37) -> 1547.96 | E19: =sum(E37) -> 1659.552 | F19: =sum(F37) -> 1737.552 | G19: =sum(G37) -> 1659.552 | H19: =sum(H37) -> 1743.552 | I19: =sum(I37) -> 1737.552 | J19: =sum(J37) -> 1737.552 | K19: =sum(K37) -> 1737.552 | ... O19: =sum(O37) -> 1659.552 | P19: =sum(D19:O19) -> 20361.032 | Q19: =iferror(averageif(D19:O19, ">0", D19:O19), 0) -> 1696.7527
C20: Expenses | D20: =sum(D55) -> 1387.96 | E20: =sum(E55) -> 1382.96 | F20: =sum(F55) -> 1447.96 | G20: =sum(G55) -> 1382.96 | H20: =sum(H55) -> 1452.96 | I20: =sum(I55) -> 1447.96 | J20: =sum(J55) -> 1447.96 | K20: =sum(K55) -> 1447.96 | ... O20: =sum(O55) -> 1382.96 | P20: =sum(D20:O20) -> 17065.52 | Q20: =iferror(averageif(D20:O20, ">0", D20:O20), 0) -> 1422.1267
C21: Net savings | D21: =D19-D20 -> 160 | E21: =E19-E20 -> 276.592 | F21: =F19-F20 -> 289.592 | G21: =G19-G20 -> 276.592 | H21: =H19-H20 -> 290.592 | I21: =I19-I20 -> 289.592 | J21: =J19-J20 -> 289.592 | K21: =K19-K20 -> 289.592 | ... O21: =O19-O20 -> 276.592 | P21: =sum(D21:O21) -> 3295.512 | Q21: =iferror(averageif(D21:O21, ">0", D21:O21), 0) -> 274.626
C22: Ending balance | D22: =(StartingBalance+D19)-D20 -> 160 | E22: =(D22+E19)-E20 -> 436.592 | F22: =(E22+F19)-F20 -> 726.184 | G22: =(F22+G19)-G20 -> 1002.776 | H22: =(G22+H19)-H20 -> 1293.368 | I22: =(H22+I19)-I20 -> 1582.96 | J22: =(I22+J19)-J20 -> 1872.552 | K22: =(J22+K19)-K20 -> 2162.144 | L22: =(K22+L19)-L20 -> 2452.736 | ... O22: =(N22+O19)-O20 -> 3295.512
C25: Income
B26: Row # | C26: {=unique(Income!A:A)} | D26: =Expenses!D$2 -> 42522 | E26: =Expenses!E$2 -> 42552 | F26: =Expenses!F$2 -> 42583 | G26: =Expenses!G$2 -> 42614 | H26: =Expenses!H$2 -> 42644 | I26: =Expenses!I$2 -> 42675 | J26: =Expenses!J$2 -> 42705 | K26: =Expenses!K$2 -> 42370 | ... O26: =Expenses!O$2 -> 42491 | P26: Total | Q26: Average
B27: {=iferror(match(C27:C36,Income!A:A,0),"")} -> 3 | C27: Contributions | D27: =if(not(isblank(B27)), indirect("Income!D"&B27&":Q"&B27),"") -> 1547.96 | E27: 1659.552 | F27: 1737.552 | G27: 1659.552 | H27: 1743.552 | I27: 1737.552 | J27: 1737.552 | K27: 1737.552 | L27: 1743.552 | M27: 1737.552 | N27: 1659.552 | O27: 1659.552 | P27: 20361.032 | Q27: 1696.7527
B28: 10 | C28: Other | D28: =if(not(isblank(B28)), indirect("Income!D"&B28&":Q"&B28),"") -> 0 | E28: 0 | F28: 0 | G28: 0 | H28: 0 | I28: 0 | J28: 0 | K28: 0 | L28: 0 | M28: 0 | N28: 0 | O28: 0 | P28: 0 | Q28: 0
D29: =if(not(isblank(B29)), indirect("Income!D"&B29&":Q"&B29),"")
D30: =if(not(isblank(B30)), indirect("Income!D"&B30&":Q"&B30),"")
D31: =if(not(isblank(B31)), indirect("Income!D"&B31&":Q"&B31),"")
D32: =if(not(isblank(B32)), indirect("Income!D"&B32&":Q"&B32),"")
D33: =if(not(isblank(B33)), indirect("Income!D"&B33&":Q"&B33),"")
D34: =if(not(isblank(B34)), indirect("Income!D"&B34&":Q"&B34),"")
D35: =if(not(isblank(B35)), indirect("Income!D"&B35&":Q"&B35),"")
D36: =if(not(isblank(B36)), indirect("Income!D"&B36&":Q"&B36),"")
C37: Total Income | D37: =SUM(D27:D28) -> 1547.96 | E37: =SUM(E27:E28) -> 1659.552 | F37: =SUM(F27:F28) -> 1737.552 | G37: =SUM(G27:G28) -> 1659.552 | H37: =SUM(H27:H28) -> 1743.552 | I37: =SUM(I27:I28) -> 1737.552 | J37: =SUM(J27:J28) -> 1737.552 | K37: =SUM(K27:K28) -> 1737.552 | ... P37: =SUM(P27:P28) -> 20361.032
C39: Expenses
B40: Row # | C40: {=unique(Expenses!A:A)} | D40: =Expenses!D$2 -> 42522 | E40: =Expenses!E$2 -> 42552 | F40: =Expenses!F$2 -> 42583 | G40: =Expenses!G$2 -> 42614 | H40: =Expenses!H$2 -> 42644 | I40: =Expenses!I$2 -> 42675 | J40: =Expenses!J$2 -> 42705 | K40: =Expenses!K$2 -> 42370 | ... O40: =Expenses!O$2 -> 42491 | P40: Total | Q40: Average
B41: {=iferror(match(C41:C55,Expenses!A:A,0),"")} -> 4 | C41: Debt | D41: =if(not(isblank(B41)), indirect("Expenses!D"&B41&":Q"&B41),"") -> 40 | E41: 40 | F41: 40 | G41: 40 | H41: 40 | I41: 40 | J41: 40 | K41: 40 | L41: 40 | M41: 40 | N41: 40 | O41: 40 | P41: 480 | Q41: 40
B42: 9 | C42: Everyday | D42: =if(not(isblank(B42)), indirect("Expenses!D"&B42&":Q"&B42),"") -> 335 | E42: 335 | F42: 335 | G42: 335 | H42: 335 | I42: 335 | J42: 335 | K42: 335 | L42: 335 | M42: 335 | N42: 335 | O42: 335 | P42: 4020 | Q42: 335
B43: 17 | C43: Health/medical | D43: =if(not(isblank(B43)), indirect("Expenses!D"&B43&":Q"&B43),"") -> 5 | E43: 5 | F43: 5 | G43: 5 | H43: 5 | I43: 5 | J43: 5 | K43: 5 | L43: 5 | M43: 5 | N43: 5 | O43: 5 | P43: 60 | Q43: 5
B44: 22 | C44: Home | D44: =if(not(isblank(B44)), indirect("Expenses!D"&B44&":Q"&B44),"") -> 554.94 | E44: 554.94 | F44: 554.94 | G44: 554.94 | H44: 554.94 | I44: 554.94 | J44: 554.94 | K44: 554.94 | L44: 554.94 | M44: 554.94 | N44: 554.94 | O44: 554.94 | P44: 6659.28 | Q44: 554.94
B45: 31 | C45: Insurance | D45: =if(not(isblank(B45)), indirect("Expenses!D"&B45&":Q"&B45),"") -> 99.65 | E45: 99.65 | F45: 99.65 | G45: 99.65 | H45: 99.65 | I45: 99.65 | J45: 99.65 | K45: 99.65 | L45: 99.65 | M45: 99.65 | N45: 99.65 | O45: 99.65 | P45: 1195.8 | Q45: 99.65
B46: 36 | C46: Pets | D46: =if(not(isblank(B46)), indirect("Expenses!D"&B46&":Q"&B46),"") -> 90 | E46: 90 | F46: 90 | G46: 90 | H46: 90 | I46: 90 | J46: 90 | K46: 90 | L46: 90 | M46: 90 | N46: 90 | O46: 90 | P46: 1080 | Q46: 90
B47: 43 | C47: Technology | D47: =if(not(isblank(B47)), indirect("Expenses!D"&B47&":Q"&B47),"") -> 10 | E47: 10 | F47: 10 | G47: 10 | H47: 10 | I47: 10 | J47: 10 | K47: 10 | L47: 10 | M47: 10 | N47: 10 | O47: 10 | P47: 120 | Q47: 10
B48: 49 | C48: Transportation | D48: =if(not(isblank(B48)), indirect("Expenses!D"&B48&":Q"&B48),"") -> 95 | E48: 90 | F48: 90 | G48: 90 | H48: 95 | I48: 90 | J48: 90 | K48: 90 | L48: 95 | M48: 90 | N48: 90 | O48: 90 | P48: 1095 | Q48: 91.25
B49: 56 | C49: Utilities | D49: =if(not(isblank(B49)), indirect("Expenses!D"&B49&":Q"&B49),"") -> 158.37 | E49: 158.37 | F49: 223.37 | G49: 158.37 | H49: 223.37 | I49: 223.37 | J49: 223.37 | K49: 223.37 | L49: 223.37 | M49: 223.37 | N49: 158.37 | O49: 158.37 | P49: 2355.44 | Q49: 196.28667
B50: 66 | C50: Other | D50: =if(not(isblank(B50)), indirect("Expenses!D"&B50&":Q"&B50),"") -> 0 | E50: 0 | F50: 0 | G50: 0 | H50: 0 | I50: 0 | J50: 0 | K50: 0 | L50: 0 | M50: 0 | N50: 0 | O50: 0 | P50: 0 | Q50: 0
D51: =if(not(isblank(B51)), indirect("Expenses!D"&B51&":Q"&B51),"")
D52: =if(not(isblank(B52)), indirect("Expenses!D"&B52&":Q"&B52),"")
D53: =if(not(isblank(B53)), indirect("Expenses!D"&B53&":Q"&B53),"")
D54: =if(not(isblank(B54)), indirect("Expenses!D"&B54&":Q"&B54),"")
C55: Total Expenses | D55: =SUM(D41:D54) -> 1387.96 | E55: =SUM(E41:E54) -> 1382.96 | F55: =SUM(F41:F54) -> 1447.96 | G55: =SUM(G41:G54) -> 1382.96 | H55: =SUM(H41:H54) -> 1452.96 | I55: =SUM(I41:I54) -> 1447.96 | J55: =SUM(J41:J54) -> 1447.96 | K55: =SUM(K41:K54) -> 1447.96 | ... P55: =SUM(P41:P54) -> 17065.52
D56: =if(not(isblank(B56)), indirect("Expenses!D"&B56&":Q"&B56),"")
D57: =if(not(isblank(B57)), indirect("Expenses!D"&B57&":Q"&B57),"")
D58: =if(not(isblank(B58)), indirect("Expenses!D"&B58&":Q"&B58),"")
D59: =if(not(isblank(B59)), indirect("Expenses!D"&B59&":Q"&B59),"")
...

Sheet Setup
B2: Annual Household budget tracker
B3: Plan and track your monthly spending for the entire year.
B6: How to use this template
A7: 1. | B7: Get started by entering your starting balance in Row 13 below.
A8: 2. | B8: Then, fill out the 'Expenses' and 'Income' tabs.
A9: 3. | B9: Feel free to rename or delete categories in these tabs. Your changes will automatically be reflected on the 'Summary' tab, which shows an overview of your projected/actual spending.
B12: Configure
B13: Starting balance: | C13: 0 | D13: People | E13: 2
